Workbook

Sheet Summary
B2: 2022-2023 EIVY USA BOOKING PROGRAM
B4: SHIP TO : | E4: PO#
E6: TOTAL :
B9: BILL TO : | F9: DEADLINE - February 1, 2022
B15: DROP ONE:
C16: BASELAYER | E16: FLEECE | G16: ACCESSORIES
C17: ='Eivy 22-23 Drop One'!I339 -> 0 | E17: ='Eivy 22-23 Drop One'!I496 -> 0 | F17: ='Eivy 22-23 Drop One'!I562 -> 0
E19: DROP ONE TOTAL: | G19: =C17+E17+F17 -> 0
B22: DROP TWO:
C23: BASELAYER | E23: FLEECE | G23: ACCESSORIES
C24: ='Eivy 22-23 Drop Two'!I213 -> 0 | E24: ='Eivy 22-23 Drop Two'!I286 -> 0 | F24: ='Eivy 22-23 Drop Two'!I311 -> 0
C26: CARRY OVER | E26: DROP TWO TOTAL: | G26: =C24+E24+F24+C27 -> 0
C27: ='Eivy 22-23 Drop Two'!I465 -> 0
E30: ORDER TOTAL: | G30: =G26+G19 -> 0
B34: NOTES:
B44: CONTACT:
A45: Foundry Distribution - 3602 Via Terra Street, Salt Lake City, Utah 84115 p. 801.994.6484 e. info@foundrydist.com

Sheet Policy
B2: DISCOUNT STRUCTURE AND POLICY
C5: ORDER TOTAL | D5: VOLUME DISCOUNT
B6: *To qualify for booking terms a minimum order of $ 1,000 must be made by order deadline | C6: $ 2, 001 - $ 5,000 | D6: 0.03
B7: *All orders are subject to availability. | C7: $ 5,001 -10,000 | D7: 0.05
B8: *Orders received after booking deadline will not be eligible for discounts. | C8: $ 10,000 + | D8: 0.07
B10: CREDIT TERMS & LIMITS
B11: * To receive discounts order MUST be submitted by order deadline. All product is Subject To Prior Sale
B12: * Booking terms are COD from the date of shipment (On Approved Credit) If minimum booking volume is not met.
B13: * Booking terms are Net 60 Days if minimum booking is met. Late Payment of 2% monthly will be applied.
B14: * After the expiration date all backorders will be shipped on regular terms.
B15: * To qualify for Eivy Booking Terms your Nitro Snowboards Canada account must be current in good standing.
B16: * Discounts may be given as a credit at time of on-time payment, for dealers with previous payment history concerns.
B17: * Pricing may be adjusted for currency decline. All Pricing is in USD
B18: * Please fill out order form completely, including signature at bottom.
B19: * PDC's may be required on orders over $ 5,000.
B20: * All orders are subject to credit approval by Foundry Distribution and may be rejected without cause or liability.
B21: * If start ship and cancel dates are not filled in on the order form, product is to ship as ready.
... B48: ALL SALES ARE SUBJECT TO TERMS AND CONDITIONS OF NITRO SNOWBOARDS AUTHORIZED DEALER APPLICATION

Sheet Eivy 22-23 Drop One
A1: EAN | B1: Code | C1: Name | D1: Color | E1: Size | F1: Wholesale | G1: Retail | H1: Order Qty | I1: Ext
A2: BASELAYERS
A3: 7330057018950 | B3: A00189075-XXS | C3: Icecold Top | D3: Team Black | E3: XXS | F3: 47.5 | G3: 94.95 | I3: =F3*H3 -> 0
A4: 7330057018967 | B4: A00189075-XS | C4: Icecold Top | D4: Team Black | E4: XS | F4: 47.5 | G4: 94.95 | I4: =F4*H4 -> 0
A5: 7330057018974 | B5: A00189075-S | C5: Icecold Top | D5: Team Black | E5: S | F5: 47.5 | G5: 94.95 | I5: =F5*H5 -> 0
A6: 7330057018981 | B6: A00189075-M | C6: Icecold Top | D6: Team Black | E6: M | F6: 47.5 | G6: 94.95 | I6: =F6*H6 -> 0
A7: 7330057018998 | B7: A00189075-L | C7: Icecold Top | D7: Team Black | E7: L | F7: 47.5 | G7: 94.95 | I7: =F7*H7 -> 0
A8: 7330057019001 | B8: A00189075-XL | C8: Icecold Top | D8: Team Black | E8: XL | F8: 47.5 | G8: 94.95 | I8: =F8*H8 -> 0
A9: 7330057019018 | B9: A00189075-XXL | C9: Icecold Top | D9: Team Black | E9: XXL | F9: 47.5 | G9: 94.95 | I9: =F9*H9 -> 0
A10: 7330057019025 | B10: A00188075-XXS | C10: Icecold Tights | D10: Team Black | E10: XXS | F10: 42.5 | G10: 84.95 | I10: =F10*H10 -> 0
A11: 7330057019032 | B11: A00188075-XS | C11: Icecold Tights | D11: Team Black | E11: XS | F11: 42.5 | G11: 84.95 | I11: =F11*H11 -> 0
A12: 7330057019049 | B12: A00188075-S | C12: Icecold Tights | D12: Team Black | E12: S | F12: 42.5 | G12: 84.95 | I12: =F12*H12 -> 0
A13: 7330057019056 | B13: A00188075-M | C13: Icecold Tights | D13: Team Black | E13: M | F13: 42.5 | G13: 84.95 | I13: =F13*H13 -> 0
A14: 7330057019063 | B14: A00188075-L | C14: Icecold Tights | D14: Team Black | E14: L | F14: 42.5 | G14: 84.95 | I14: =F14*H14 -> 0
... A128: 7330057026962 | B128: A00247091-XXL | C128: Icecold Tights | D128: Pink Cheetah | E128: XXL | F128: 42.5 | G128: 84.95 | I128: =F128*H128 -> 0
A129: 7330057025279 | B129: A00191077-XXS | C129: Icecold Gaiter Top | D129: Snow Leopard | E129: XXS | F129: 47.5 | G129: 94.95 | I129: =F129*H129 -> 0
A130: 7330057025286 | B130: A00191077-XS | C130: Icecold Gaiter Top | D130: Snow Leopard | E130: XS | F130: 47.5 | G130: 94.95 | I130: =F130*H130 -> 0
A131: 7330057025293 | B131: A00191077-S | C131: Icecold Gaiter Top | D131: Snow Leopard | E131: S | F131: 47.5 | G131: 94.95 | I131: =F131*H131 -> 0
A132: 7330057025309 | B132: A00191077-M | C132: Icecold Gaiter Top | D132: Snow Leopard | E132: M | F132: 47.5 | G132: 94.95 | I132: =F132*H132 -> 0
A133: 7330057025316 | B133: A00191077-L | C133: Icecold Gaiter Top | D133: Snow Leopard | E133: L | F133: 47.5 | G133: 94.95 | I133: =F133*H133 -> 0
A134: 7330057025323 | B134: A00191077-XL | C134: Icecold Gaiter Top | D134: Snow Leopard | E134: XL | F134: 47.5 | G134: 94.95 | I134: =F134*H134 -> 0
A135: 7330057025330 | B135: A00191077-XXL | C135: Icecold Gaiter Top | D135: Snow Leopard | E135: XXL | F135: 47.5 | G135: 94.95 | I135: =F135*H135 -> 0
A136: 7330057019797 | B136: A00188077-XXS | C136: Icecold Tights | D136: Snow Leopard | E136: XXS | F136: 42.5 | G136: 84.95 | I136: =F136*H136 -> 0
A137: 7330057019803 | B137: A00188077-XS | C137: Icecold Tights | D137: Snow Leopard | E137: XS | F137: 42.5 | G137: 84.95 | I137: =F137*H137 -> 0
A138: 7330057019810 | B138: A00188077-S | C138: Icecold Tights | D138: Snow Leopard | E138: S | F138: 42.5 | G138: 84.95 | I138: =F138*H138 -> 0
A139: 7330057019827 | B139: A00188077-M | C139: Icecold Tights | D139: Snow Leopard | E139: M | F139: 42.5 | G139: 84.95 | I139: =F139*H139 -> 0
A140: 7330057019834 | B140: A00188077-L | C140: Icecold Tights | D140: Snow Leopard | E140: L | F140: 42.5 | G140: 84.95 | I140: =F140*H140 -> 0
A141: 7330057019841 | B141: A00188077-XL | C141: Icecold Tights | D141: Snow Leopard | E141: XL | F141: 42.5 | G141: 84.95 | I141: =F141*H141 -> 0
A142: 7330057019858 | B142: A00188077-XXL | C142: Icecold Tights | D142: Snow Leopard | E142: XXL | F142: 42.5 | G142: 84.95 | I142: =F142*H142 -> 0
A143: 7330057026979 | B143: A00240092-XXS | C143: Icecold Gaiter Top | D143: Abstract Shapes | E143: XXS | F143: 47.5 | G143: 94.95 | I143: =F143*H143 -> 0
A144: 7330057026986 | B144: A00240092-XS | C144: Icecold Gaiter Top | D144: Abstract Shapes | E144: XS | F144: 47.5 | G144: 94.95 | I144: =F144*H144 -> 0
A145: 7330057026993 | B145: A00240092-S | C145: Icecold Gaiter Top | D145: Abstract Shapes | E145: S | F145: 47.5 | G145: 94.95 | I145: =F145*H145 -> 0
A146: 7330057027006 | B146: A00240092-M | C146: Icecold Gaiter Top | D146: Abstract Shapes | E146: M | F146: 47.5 | G146: 94.95 | I146: =F146*H146 -> 0
A147: 7330057027013 | B147: A00240092-L | C147: Icecold Gaiter Top | D147: Abstract Shapes | E147: L | F147: 47.5 | G147: 94.95 | I147: =F147*H147 -> 0
... A338: 7330057028089 | B338: A00247095-XXL | C338: Icecold Tights | D338: Black & Offwhite | E338: XXL | F338: 42.5 | G338: 84.95 | I338: =F338*H338 -> 0
G339: Total: | H339: =SUM(H3:H338) -> 0 | I339: =SUM(I3:I338) -> 0
A341: FLEECE
A342: 7330057021752 | B342: A00198075-XXS | C342: Peg Cropped Fleece | D342: Team Black | E342: XXS | F342: 47.5 | G342: 94.95 | I342: =F342*H342 -> 0
A343: 7330057021769 | B343: A00198075-XS | C343: Peg Cropped Fleece | D343: Team Black | E343: XS | F343: 47.5 | G343: 94.95 | I343: =F343*H343 -> 0
A344: 7330057021776 | B344: A00198075-S | C344: Peg Cropped Fleece | D344: Team Black | E344: S | F344: 47.5 | G344: 94.95 | I344: =F344*H344 -> 0
...

Sheet Eivy 22-23 Drop Two
A1: EAN | B1: Code | C1: Name | D1: Color | E1: Size | F1: Wholesale | G1: Retail | H1: Order Qty | I1: Ext
A2: Baselayer
A3: 7330057023657 | B3: A00219086-XXS | C3: Icecold Rib Top | D3: Faded Amber | E3: XXS | F3: 47.5 | G3: 94.95 | I3: =H3*F3 -> 0
A4: 7330057023664 | B4: A00219086-XS | C4: Icecold Rib Top | D4: Faded Amber | E4: XS | F4: 47.5 | G4: 94.95 | I4: =H4*F4 -> 0
A5: 7330057023671 | B5: A00219086-S | C5: Icecold Rib Top | D5: Faded Amber | E5: S | F5: 47.5 | G5: 94.95 | I5: =H5*F5 -> 0
A6: 7330057023688 | B6: A00219086-M | C6: Icecold Rib Top | D6: Faded Amber | E6: M | F6: 47.5 | G6: 94.95 | I6: =H6*F6 -> 0
A7: 7330057023695 | B7: A00219086-L | C7: Icecold Rib Top | D7: Faded Amber | E7: L | F7: 47.5 | G7: 94.95 | I7: =H7*F7 -> 0
A8: 7330057023701 | B8: A00219086-XL | C8: Icecold Rib Top | D8: Faded Amber | E8: XL | F8: 47.5 | G8: 94.95 | I8: =H8*F8 -> 0
A9: 7330057023718 | B9: A00219086-XXL | C9: Icecold Rib Top | D9: Faded Amber | E9: XXL | F9: 47.5 | G9: 94.95 | I9: =H9*F9 -> 0
A10: 7330057023725 | B10: A00222086-XXS | C10: Icecold Rib Tights | D10: Faded Amber | E10: XXS | F10: 42.5 | G10: 84.95 | I10: =H10*F10 -> 0
A11: 7330057023732 | B11: A00222086-XS | C11: Icecold Rib Tights | D11: Faded Amber | E11: XS | F11: 42.5 | G11: 84.95 | I11: =H11*F11 -> 0
A12: 7330057023749 | B12: A00222086-S | C12: Icecold Rib Tights | D12: Faded Amber | E12: S | F12: 42.5 | G12: 84.95 | I12: =H12*F12 -> 0
A13: 7330057023756 | B13: A00222086-M | C13: Icecold Rib Tights | D13: Faded Amber | E13: M | F13: 42.5 | G13: 84.95 | I13: =H13*F13 -> 0
A14: 7330057023763 | B14: A00222086-L | C14: Icecold Rib Tights | D14: Faded Amber | E14: L | F14: 42.5 | G14: 84.95 | I14: =H14*F14 -> 0
... A82: 7330057024449 | B82: A00222088-S | C82: Icecold Rib Tights | D82: Faded Oak | E82: S | F82: 42.5 | G82: 84.95 | I82: =H82*F82 -> 0
A83: 7330057024456 | B83: A00222088-M | C83: Icecold Rib Tights | D83: Faded Oak | E83: M | F83: 42.5 | G83: 84.95 | I83: =H83*F83 -> 0
A84: 7330057024463 | B84: A00222088-L | C84: Icecold Rib Tights | D84: Faded Oak | E84: L | F84: 42.5 | G84: 84.95 | I84: =H84*F84 -> 0
A85: 7330057024470 | B85: A00222088-XL | C85: Icecold Rib Tights | D85: Faded Oak | E85: XL | F85: 42.5 | G85: 84.95 | I85: =H85*F85 -> 0
A86: 7330057024487 | B86: A00222088-XXL | C86: Icecold Rib Tights | D86: Faded Oak | E86: XXL | F86: 42.5 | G86: 84.95 | I86: =H86*F86 -> 0
A87: 7330057024494 | B87: A00224088-XXS | C87: Rider Rib Sports Bra | D87: Faded Oak | E87: XXS | F87: 25 | G87: 49.95 | I87: =H87*F87 -> 0
A88: 7330057024500 | B88: A00224088-XS | C88: Rider Rib Sports Bra | D88: Faded Oak | E88: XS | F88: 25 | G88: 49.95 | I88: =H88*F88 -> 0
A89: 7330057024517 | B89: A00224088-S | C89: Rider Rib Sports Bra | D89: Faded Oak | E89: S | F89: 25 | G89: 49.95 | I89: =H89*F89 -> 0
A90: 7330057024524 | B90: A00224088-M | C90: Rider Rib Sports Bra | D90: Faded Oak | E90: M | F90: 25 | G90: 49.95 | I90: =H90*F90 -> 0
A91: 7330057024531 | B91: A00224088-L | C91: Rider Rib Sports Bra | D91: Faded Oak | E91: L | F91: 25 | G91: 49.95 | I91: =H91*F91 -> 0
A92: 7330057024548 | B92: A00224088-XL | C92: Rider Rib Sports Bra | D92: Faded Oak | E92: XL | F92: 25 | G92: 49.95 | I92: =H92*F92 -> 0
A93: 7330057024555 | B93: A00224088-XXL | C93: Rider Rib Sports Bra | D93: Faded Oak | E93: XXL | F93: 25 | G93: 49.95 | I93: =H93*F93 -> 0
A94: 7330057024562 | B94: A00221088-XXS | C94: Venture Rib Top | D94: Faded Oak | E94: XXS | F94: 47.5 | G94: 94.95 | I94: =H94*F94 -> 0
... A142: 7330057025040 | B142: A00223089-XXL | C142: Harlem Rib Travel Pants | D142: Faded Woodrose | E142: XXL | F142: 47.5 | G142: 94.95 | I142: =H142*F142 -> 0
A143: 7330057029277 | B143: A00267098-XXS | C143: Icecold Rib Top | D143: Deep Sea | E143: XXS | F143: 47.5 | G143: 94.95 | I143: =H143*F143 -> 0
A144: 7330057029284 | B144: A00267098-XS | C144: Icecold Rib Top | D144: Deep Sea | E144: XS | F144: 47.5 | G144: 94.95 | I144: =H144*F144 -> 0
A145: 7330057029291 | B145: A00267098-S | C145: Icecold Rib Top | D145: Deep Sea | E145: S | F145: 47.5 | G145: 94.95 | I145: =H145*F145 -> 0
A146: 7330057029307 | B146: A00267098-M | C146: Icecold Rib Top | D146: Deep Sea | E146: M | F146: 47.5 | G146: 94.95 | I146: =H146*F146 -> 0
A147: 7330057029314 | B147: A00267098-L | C147: Icecold Rib Top | D147: Deep Sea | E147: L | F147: 47.5 | G147: 94.95 | I147: =H147*F147 -> 0
A148: 7330057029321 | B148: A00267098-XL | C148: Icecold Rib Top | D148: Deep Sea | E148: XL | F148: 47.5 | G148: 94.95 | I148: =H148*F148 -> 0
A149: 7330057029338 | B149: A00267098-XXL | C149: Icecold Rib Top | D149: Deep Sea | E149: XXL | F149: 47.5 | G149: 94.95 | I149: =H149*F149 -> 0
A150: 7330057029345 | B150: A00271098-XXS | C150: Icecold Rib Tights | D150: Deep Sea | E150: XXS | F150: 42.5 | G150: 84.95 | I150: =H150*F150 -> 0
A151: 7330057029352 | B151: A00271098-XS | C151: Icecold Rib Tights | D151: Deep Sea | E151: XS | F151: 42.5 | G151: 84.95 | I151: =H151*F151 -> 0
A152: 7330057029369 | B152: A00271098-S | C152: Icecold Rib Tights | D152: Deep Sea | E152: S | F152: 42.5 | G152: 84.95 | I152: =H152*F152 -> 0
A153: 7330057029376 | B153: A00271098-M | C153: Icecold Rib Tights | D153: Deep Sea | E153: M | F153: 42.5 | G153: 84.95 | I153: =H153*F153 -> 0
A154: 7330057029383 | B154: A00271098-L | C154: Icecold Rib Tights | D154: Deep Sea | E154: L | F154: 42.5 | G154: 84.95 | I154: =H154*F154 -> 0
...
