Workbook
Name JET: [1]LUGGAGE!#REF!
Name JET: #REF!

Sheet Summary
B2: 2022-2023 L1 PREMIUM GOODS USA BOOKING PROGRAM
B4: BILL TO: | E4: PO#
E6: TOTAL:
B9: SHIP TO: | F9: DEADLINE - January 21, 2022
B15: ORDER SUMMARY:
C16: THEOREM | E16: MENS FOUNDATION | G16: WOMEN'S FOUNDATION
C17: ='L1'!I214 -> 0 | E17: ='L1'!I572 -> 0 | F17: ='L1'!I865 -> 0
C19: APPAREL | E19: HANDWEAR | G19: HEADWEAR
C20: ='L1'!I1070 -> 0 | E20: ='L1'!I1153 -> 0 | G20: ='L1'!I1184 -> 0
B22: ORDER TOTAL: | C22: =C17+E17+F17+C20+E20+G20 -> 0
B25: Notes:
B36: Contact:
A37: Foundry Distribution - 3602 Via Terra Street, Salt Lake City, Utah 84115
A38: p. 801.994.6484 e. info@foundrydist.com

Sheet Policy
B2: L1 PREMIUM GOODS
B3: DISCOUNT STRUCTURE AND POLICY
B5: SOFTGOODS & ACCESSORIES | C5: ORDER TOTAL | D5: VOLUME DISCOUNT
B6: *To qualify for preseason softgoods booking terms a minimum order of $10, 000 must be made by order deadline. | C6: $ 10, 001 - $ 20, 000 | D6: 0.03
B7: *All orders are subject to availability. | C7: $ 20, 001 - $ 50, 000 | D7: 0.04
B8: *Orders received after booking deadline will not be eligible for discounts. | C8: $ 50, 001 - $ 80, 000 | D8: 0.05
C9: $ 80, 001 + | D9: 0.06
B11: BONUS DISCOUNTS | D11: DISCOUNT
B12: * Factory Deadline Discount: Orders Received by booking Dealine of January 21st, 2022. | D12: 0.02
B14: M.A.P POLICY
B15: March 1st, 2023 - MAP Down to 20% Off
B16: April 1, 2023 - MAP Down to 30% Off
B17: May 1, 2023 - MAP Down to 40% Off
B19: CREDIT TERMS & LIMITS
B20: * To receive discounts order MUST be submitted by order deadline. All product is Subject To Prior Sale
B21: * Booking terms are Net 30 from the date of delivery (On Approved Credit) If minimum booking volume is not met.
B22: * Booking terms are Net 90 Days If booking minimum booking volume is met.
B23: * After the expiration date all backorders will be shipped on regular terms.
B24: * To qualify for L1 Premium Goods Booking Terms, your account must be current in good standing.
B25: * Discounts may be given as a credit at time of on-time payment, for dealers with previous payment history concerns.
B26: * Pricing may be adjusted for currency decline and tarrif structure changes.
... B52: ALL SALES ARE SUBJECT TO TERMS AND CONDITIONS OF NITRO SNOWBOARDS AUTHORIZED DEALER APPLICATION

Sheet L1
A1: UPC | B1: SKU | C1: PRODUCT | D1: COLOUR | E1: SIZE | F1: WHSL | G1: RETAIL | H1: QUANTITY | I1: EXT
A3: THEORUM -MENS
A4: 7630221827877 | B4: N873850-001S | C4: 2023 ALPHA | D4: PHANTOM | E4: S | F4: 230 | G4: 459.95 | I4: =H4*F4 -> 0
A5: 7630221827884 | B5: N873850-001M | C5: 2023 ALPHA | D5: PHANTOM | E5: M | F5: 230 | G5: 459.95 | I5: =H5*F5 -> 0
A6: 7630221827891 | B6: N873850-001L | C6: 2023 ALPHA | D6: PHANTOM | E6: L | F6: 230 | G6: 459.95 | I6: =H6*F6 -> 0
A7: 7630221827907 | B7: N873850-001XL | C7: 2023 ALPHA | D7: PHANTOM | E7: XL | F7: 230 | G7: 459.95 | I7: =H7*F7 -> 0
A8: 7630221827914 | B8: N873850-001XXL | C8: 2023 ALPHA | D8: PHANTOM | E8: XXL | F8: 230 | G8: 459.95 | I8: =H8*F8 -> 0
A9: 7630221827921 | B9: N873850-002S | C9: 2023 ALPHA | D9: CHILI | E9: S | F9: 230 | G9: 459.95 | I9: =H9*F9 -> 0
A10: 7630221827938 | B10: N873850-002M | C10: 2023 ALPHA | D10: CHILI | E10: M | F10: 230 | G10: 459.95 | I10: =H10*F10 -> 0
A11: 7630221827945 | B11: N873850-002L | C11: 2023 ALPHA | D11: CHILI | E11: L | F11: 230 | G11: 459.95 | I11: =H11*F11 -> 0
A12: 7630221827952 | B12: N873850-002XL | C12: 2023 ALPHA | D12: CHILI | E12: XL | F12: 230 | G12: 459.95 | I12: =H12*F12 -> 0
A13: 7630221827969 | B13: N873850-002XXL | C13: 2023 ALPHA | D13: CHILI | E13: XXL | F13: 230 | G13: 459.95 | I13: =H13*F13 -> 0
A14: 7630221827976 | B14: N873850-003S | C14: 2023 ALPHA | D14: MOSS | E14: S | F14: 230 | G14: 459.95 | I14: =H14*F14 -> 0
A15: 7630221827983 | B15: N873850-003M | C15: 2023 ALPHA | D15: MOSS | E15: M | F15: 230 | G15: 459.95 | I15: =H15*F15 -> 0
... A93: 7630221830709 | B93: N873866-003XXL | C93: 2023 GEMINI | D93: MOSS | E93: XXL | F93: 175 | G93: 349.95 | I93: =H93*F93 -> 0
A94: THEORUM -UNISEX
A95: 7630221828171 | B95: N873852-001XS | C95: 2023 AXIAL JACKET | D95: PHANTOM | E95: XS | F95: 200 | G95: 399.95 | I95: =H95*F95 -> 0
A96: 7630221828188 | B96: N873852-001S | C96: 2023 AXIAL JACKET | D96: PHANTOM | E96: S | F96: 200 | G96: 399.95 | I96: =H96*F96 -> 0
A97: 7630221828195 | B97: N873852-001M | C97: 2023 AXIAL JACKET | D97: PHANTOM | E97: M | F97: 200 | G97: 399.95 | I97: =H97*F97 -> 0
A98: 7630221828201 | B98: N873852-001L | C98: 2023 AXIAL JACKET | D98: PHANTOM | E98: L | F98: 200 | G98: 399.95 | I98: =H98*F98 -> 0
A99: 7630221828218 | B99: N873852-001XL | C99: 2023 AXIAL JACKET | D99: PHANTOM | E99: XL | F99: 200 | G99: 399.95 | I99: =H99*F99 -> 0
A100: 7630221828225 | B100: N873852-001XXL | C100: 2023 AXIAL JACKET | D100: PHANTOM | E100: XXL | F100: 200 | G100: 399.95 | I100: =H100*F100 -> 0
A101: 7630221828232 | B101: N873852-002XS | C101: 2023 AXIAL JACKET | D101: SPRAY | E101: XS | F101: 200 | G101: 399.95 | I101: =H101*F101 -> 0
A102: 7630221828249 | B102: N873852002S | C102: 2023 AXIAL JACKET | D102: SPRAY | E102: S | F102: 200 | G102: 399.95 | I102: =H102*F102 -> 0
A103: 7630221828256 | B103: N873852002M | C103: 2023 AXIAL JACKET | D103: SPRAY | E103: M | F103: 200 | G103: 399.95 | I103: =H103*F103 -> 0
A104: 7630221828263 | B104: N873852002L | C104: 2023 AXIAL JACKET | D104: SPRAY | E104: L | F104: 200 | G104: 399.95 | I104: =H104*F104 -> 0
A105: 7630221828270 | B105: N873852002XL | C105: 2023 AXIAL JACKET | D105: SPRAY | E105: XL | F105: 200 | G105: 399.95 | I105: =H105*F105 -> 0
A106: 7630221828287 | B106: N873852002XXL | C106: 2023 AXIAL JACKET | D106: SPRAY | E106: XXL | F106: 200 | G106: 399.95 | I106: =H106*F106 -> 0
... A142: 7630221830945 | B142: N873867-004XXL | C142: 2023 AXIAL PANT | D142: ULTRAVIOLET | E142: XXL | F142: 175 | G142: 349.95 | I142: =H142*F142 -> 0
A143: THEORUM - WOMEN'S
A144: 7630221832802 | B144: N873878-001XS | C144: 2023 NIGHTWAVE | D144: MOSS | E144: XS | F144: 230 | G144: 459.95 | I144: =H144*F144 -> 0
A145: 7630221832819 | B145: N873878-001S | C145: 2023 NIGHTWAVE | D145: MOSS | E145: S | F145: 230 | G145: 459.95 | I145: =H145*F145 -> 0
A146: 7630221832826 | B146: N873878-001M | C146: 2023 NIGHTWAVE | D146: MOSS | E146: M | F146: 230 | G146: 459.95 | I146: =H146*F146 -> 0
A147: 7630221832833 | B147: N873878-001L | C147: 2023 NIGHTWAVE | D147: MOSS | E147: L | F147: 230 | G147: 459.95 | I147: =H147*F147 -> 0
A148: 7630221847790 | B148: N873878-001XL | C148: 2023 NIGHTWAVE | D148: MOSS | E148: XL | F148: 230 | G148: 459.95 | I148: =H148*F148 -> 0
A149: 7630221832840 | B149: N873878-002XS | C149: 2023 NIGHTWAVE | D149: ULTRAVIOLET | E149: XS | F149: 230 | G149: 459.95 | I149: =H149*F149 -> 0
A150: 7630221832857 | B150: N873878-002S | C150: 2023 NIGHTWAVE | D150: ULTRAVIOLET | E150: S | F150: 230 | G150: 459.95 | I150: =H150*F150 -> 0
A151: 7630221832864 | B151: N873878-002M | C151: 2023 NIGHTWAVE | D151: ULTRAVIOLET | E151: M | F151: 230 | G151: 459.95 | I151: =H151*F151 -> 0
A152: 7630221832871 | B152: N873878-002L | C152: 2023 NIGHTWAVE | D152: ULTRAVIOLET | E152: L | F152: 230 | G152: 459.95 | I152: =H152*F152 -> 0
A153: 7630221847806 | B153: N873878-002XL | C153: 2023 NIGHTWAVE | D153: ULTRAVIOLET | E153: XL | F153: 230 | G153: 459.95 | I153: =H153*F153 -> 0
...
